File: Gr_YC_2.txt
#Acq. time (s)=	5
#Accumulations=	5
#Range (cm-¹)=	1000...3000
#Windows=	6
#Autofocus=	Off
#AutoExposure=	Off
#Spike filter=	Multiple accum.
#Delay time (s)=	0
#Binning=	1
#Readout mode=	Signal
#DeNoise=	Standard
#ICS correction=	Off
#Dark correction=	Off
#Inst. Process=	Off
#Detector temperature (°C)=	-65
#Instrument=	ARAMIS
#Detector=	Andor CCD
#Objective=	x100
#Grating=	1800
#Filter=	100%
#Laser (nm)=	633
#Slit=	100
#Location=	Micro
#Range=	Visible
#StageXY=	Marzhauser
#X (µm)=	6146.2
#Y (µm)=	-799.7
#Full time(mm:ss)=	2:42
#Project=
#Sample=
#Site=
#Title=	Gr_YC_1
#Remark=
#Date=	02.07.2025 13:42
#Acquired=	02.07.2025 13:42:36
1001.64	109.842
1003.6	102.691
1005.57	94.3975
1007.53	88.9272
1009.49	83.4854
1011.45	72.2313
1013.4	66.1619
1015.36	62.1533
1017.32	58.8357
1019.27	55.6102
1021.23	50.9574
1023.18	47.4178
1025.13	43.4089
1027.09	40.1065
1029.04	36.7906
1030.99	32.1739
1032.93	26.478
1034.88	21.9755
1036.83	18.7036
1038.78	15.5227
1040.72	11.5393
1042.66	7.42379
1044.61	3.63006
1046.55	3.0174
1048.49	2.88349
1050.43	3.26598
1052.37	1.83813
1054.31	2.21904
1056.25	2.49319
1058.18	2.42644
1060.12	-0.157816
1062.05	-2.02209
1063.99	-1.30042
1065.92	-0.163091
1067.85	-0.192608
1069.78	-0.4489
1071.71	-0.917445
1073.64	0.143218
1075.57	-0.363858
1077.49	-0.431709
1079.42	-0.684658
1081.35	-0.546686
1083.27	-0.456771
1085.19	-0.295744
1087.12	-0.107239
1089.04	-0.370246
1090.96	0.776945
1092.88	0.945278
1094.8	1.50264
1096.71	-0.689535
1098.63	-1.51297
1100.54	-1.43417
1102.46	-1.0525
1104.37	-3.41911
1106.29	-0.190523
1108.2	-0.184856
1110.11	-0.861113
1112.02	-1.61254
1113.93	-1.4011
1115.84	-1.77314
1117.74	-2.24949
1119.65	-2.08315
1121.56	-3.19446
1123.46	-2.95155
1125.36	-2.64197
1127.27	-2.21273
1129.17	-1.83442
1131.07	-1.48807
1132.97	-1.43894
1134.87	-1.42693
1136.77	-2.92465
1138.66	-4.31371
1140.56	-4.43043
1142.45	-2.66458
1144.35	-1.82993
1146.24	-1.86555
1148.13	-2.28098
1150.02	-3.12431
1151.91	-3.11118
1153.8	-2.95767
1155.69	-2.45275
1157.58	-2.91781
1159.47	-2.87295
1161.35	-3.20896
1163.24	-3.3787
1165.12	-4.222
1167	-4.3104
1168.89	-4.99881
1170.77	-5.36958
1172.65	-5.73589
1174.53	-4.59766
1176.4	-2.48647
1178.28	-2.18212
1180.16	-3.1877
1182.03	-5.0562
1183.91	-5.71598
1185.78	-4.8501
1187.65	-3.98584
1189.53	-4.51289
1191.4	-4.81701
1193.27	-5.37314
1195.14	-4.40471
1197	-4.21416
1198.87	-4.87898
1200.74	-5.29907
1202.6	-5.32914
1204.47	-5.59107
1206.33	-5.28212
1208.19	-5.17338
1210.06	-5.15415
1211.92	-5.76117
1213.78	-4.81114
1215.63	-4.14589
1217.49	-4.11652
1219.35	-4.57412
1221.21	-4.96884
1223.06	-5.46035
1224.91	-5.99682
1226.77	-6.12018
1228.62	-6.2299
1230.47	-6.53681
1232.32	-5.2722
1234.17	-4.82036
1236.02	-4.43996
1237.87	-4.34814
1239.71	-5.15307
1241.56	-5.31497
1243.4	-5.30344
1245.25	-4.99365
1247.09	-4.32883
1248.93	-5.62988
1250.77	-4.81156
1252.62	-5.07491
1254.45	-5.34261
1256.29	-5.06276
1258.13	-5.34268
1259.97	-5.69143
1261.8	-6.17238
1263.64	-5.71807
1265.47	-4.7304
1267.3	-4.4161
1269.14	-4.68746
1270.97	-4.07769
1272.8	-4.20727
1274.63	-4.14602
1276.46	-4.17052
1278.28	-4.03918
1280.11	-2.91285
1281.94	-2.85682
1283.76	-2.94313
1285.58	-2.7438
1287.41	-2.52528
1289.23	-2.05197
1291.05	-2.4878
1292.87	-3.49423
1294.69	-3.97017
1296.51	-3.25111
1298.32	-3.13625
1300.14	-3.2218
1301.96	-3.85511
1303.77	-4.37564
1305.58	-4.11775
1307.4	-2.58502
1309.21	-1.99705
1311.02	-2.35302
1312.83	-2.42984
1314.64	-3.13783
1316.45	-3.68486
1318.25	-2.89216
1320.06	-3.81419
1321.87	-4.50835
1323.67	-4.3911
1325.47	-3.76096
1327.28	-3.33071
1329.08	-3.50697
1330.88	-5.59394
1332.68	-5.93374
1334.48	-4.47992
1336.28	-4.25794
1338.07	-5.3638
1339.87	-5.80343
1341.67	-5.92309
1343.46	-5.72241
1345.25	-4.70096
1347.05	-4.54459
1348.84	-3.85652
1350.63	-4.24683
1352.42	-5.28573
1354.21	-5.66296
1356	-5.43949
1357.78	-5.36532
1359.57	-5.84043
1361.36	-6.26911
1363.14	-5.13488
1364.92	-4.73996
1366.71	-5.12916
1368.49	-5.55286
1370.27	-6.10877
1372.05	-6.26029
1373.83	-6.79897
1375.61	-6.05654
1377.38	-5.58897
1379.16	-4.75536
1380.94	-5.53571
1382.71	-5.93996
1384.48	-5.74087
1386.26	-5.28387
1388.03	-5.65521
1389.8	-6.39667
1391.57	-6.23471
1393.34	-5.80185
1395.11	-6.00254
1396.87	-6.23044
1398.64	-6.50002
1400.41	-6.50008
1402.17	-5.83069
1403.93	-5.39233
1405.7	-4.95304
1407.46	-5.0894
1409.22	-4.90418
1410.98	-5.17555
1412.74	-5.84759
1414.5	-5.3393
1416.26	-4.81319
1418.01	-4.62899
1419.77	-4.64752
1421.52	-4.53715
1423.28	-4.20171
1425.03	-3.87372
1426.78	-3.74537
1428.53	-4.75824
1430.28	-3.8564
1432.03	-4.08137
1433.78	-4.55765
1435.53	-4.70634
1437.27	-4.61775
1439.02	-3.32833
1440.76	-3.38841
1442.51	-3.7661
1444.25	-3.77585
1445.99	-4.32251
1447.73	-5.40833
1449.47	-6.29748
1451.21	-5.78104
1452.95	-5.35963
1454.69	-4.87933
1456.43	-4.86263
1458.16	-5.6751
1459.9	-5.75441
1461.63	-5.08889
1463.37	-4.21281
1465.1	-5.19939
1466.83	-6.33901
1468.56	-5.34641
1470.29	-5.31884
1472.02	-4.6159
1473.59	-4.97841
1475.37	-5.50127
1477.16	-6.67843
1478.94	-6.10712
1480.72	-7.41942
1482.5	-5.63811
1484.29	-6.25598
1486.07	-5.82322
1487.85	-5.09894
1489.62	-5.73476
1491.4	-5.73811
1493.18	-5.36759
1494.95	-6.0832
1496.73	-6.83419
1498.5	-7.53873
1500.28	-7.19963
1502.05	-7.05979
1503.82	-6.29587
1505.59	-5.2649
1507.36	-4.81558
1509.13	-5.66228
1510.9	-6.30348
1512.67	-6.37617
1514.43	-7.35561
1516.2	-7.75736
1517.96	-6.02155
1519.73	-4.79111
1521.49	-4.89412
1523.25	-5.29715
1525.01	-5.58693
1526.77	-5.26676
1528.53	-4.61877
1530.29	-5.16855
1532.05	-5.61977
1533.81	-5.60836
1535.56	-5.79103
1537.32	-5.34568
1539.07	-5.61771
1540.82	-5.6003
1542.58	-5.14339
1544.33	-3.32622
1546.08	-2.74126
1547.83	-2.39812
1549.58	-1.79347
1551.33	-1.02564
1553.08	0.179686
1554.82	0.19023
1556.57	-0.521162
1558.31	-0.403701
1560.06	1.97506
1561.8	4.41663
1563.54	7.69951
1565.28	11.623
1567.02	16.7418
1568.76	22.5595
1570.5	31.1827
1572.24	43.3125
1573.98	57.0082
1575.71	68.5225
1577.45	71.8313
1579.18	65.6061
1580.92	49.4877
1582.65	34.0882
1584.38	22.7628
1586.11	14.9909
1587.85	9.78576
1589.57	6.55385
1591.3	4.31301
1593.03	2.29552
1594.76	1.0484
1596.48	-0.294385
1598.21	-1.08127
1599.93	-1.34629
1601.66	-1.60015
1603.38	-2.80254
1605.1	-3.18341
1606.82	-2.68785
1608.54	-2.00457
1610.26	-2.06964
1611.98	-2.69402
1613.7	-3.46225
1615.41	-3.89516
1617.13	-4.2452
1618.84	-4.4728
1620.56	-5.66463
1622.27	-5.04936
1623.99	-4.53642
1625.7	-4.31333
1627.41	-4.22644
1629.12	-3.91279
1630.83	-3.5078
1632.53	-3.51454
1634.24	-3.66625
1635.95	-3.92589
1637.65	-4.4336
1639.36	-5.06931
1641.06	-5.13722
1642.77	-6.15022
1644.47	-7.12139
1646.17	-6.55182
1647.87	-5.98075
1649.57	-5.8109
1651.27	-5.49234
1652.97	-5.4518
1654.66	-5.23356
1656.36	-5.10439
1658.06	-5.12816
1659.75	-5.9386
1661.44	-6.67901
1663.14	-5.82255
1664.83	-5.08014
1666.52	-4.1315
1668.21	-4.28787
1669.9	-5.25172
1671.59	-5.66984
1673.28	-5.86188
1674.96	-5.41161
1676.65	-4.78671
1678.34	-4.48484
1680.02	-4.76329
1681.7	-5.79757
1683.39	-6.90671
1685.07	-6.47169
1686.75	-5.78637
1688.43	-5.52735
1690.11	-6.59155
1691.79	-8.62519
1693.46	-8.93714
1695.14	-7.60669
1696.82	-6.65887
1698.49	-6.2743
1700.17	-7.34636
1701.84	-7.76631
1703.51	-8.06115
1705.19	-6.70665
1706.86	-6.06964
1708.53	-5.94504
1710.2	-5.95237
1711.86	-5.75429
1713.53	-5.49312
1715.2	-5.67802
1716.87	-6.68659
1718.53	-6.802
1720.19	-6.18269
1721.86	-6.31741
1723.52	-7.02953
1725.18	-7.12029
1726.84	-6.48124
1728.5	-6.23788
1730.16	-6.52681
1731.82	-6.81966
1733.48	-7.25313
1735.14	-7.62073
1736.79	-7.24263
1738.45	-6.61936
1740.1	-5.93475
1741.75	-6.65233
1743.41	-6.89343
1745.06	-6.85526
1746.71	-6.6574
1748.36	-6.61888
1750.01	-7.77387
1751.66	-7.65128
1753.3	-6.83538
1754.95	-5.5478
1756.6	-4.97935
1758.24	-6.03906
1759.89	-7.24596
1761.53	-7.59332
1763.17	-6.5057
1764.81	-6.55994
1766.46	-6.45571
1768.09	-5.80915
1769.73	-5.29545
1771.37	-5.07448
1773.01	-5.18607
1774.65	-5.74457
1776.28	-6.27688
1777.92	-6.40596
1779.55	-6.59166
1781.19	-6.32514
1782.82	-6.35125
1784.45	-6.63029
1786.08	-6.48174
1787.71	-6.00859
1789.34	-5.84751
1790.97	-5.61076
1792.6	-5.55834
1794.22	-4.80136
1795.85	-5.24754
1797.47	-5.30258
1799.1	-4.79418
1800.72	-4.74526
1802.34	-4.96559
1803.97	-5.53205
1805.59	-5.78055
1807.21	-5.31608
1808.83	-5.2248
1810.44	-5.0823
1812.06	-4.57405
1813.68	-4.76162
1815.29	-5.00942
1816.91	-5.51577
1818.52	-5.15698
1820.14	-4.87989
1821.75	-4.67086
1823.36	-6.2678
1824.97	-5.41731
1826.58	-4.98444
1828.19	-5.6715
1829.8	-5.90719
1831.41	-5.6473
1833.02	-6.08935
1834.62	-6.39885
1836.23	-7.74856
1837.83	-7.24909
1839.44	-6.74637
1841.04	-5.83832
1842.64	-5.78447
1844.24	-5.84674
1845.84	-5.99277
1847.44	-5.89049
1849.04	-6.09449
1850.64	-6.18151
1852.23	-6.11951
1853.83	-5.77257
1855.43	-5.4739
1857.02	-5.68285
1858.61	-5.06191
1860.21	-5.34366
1861.8	-5.37686
1863.08	-5.48061
1864.72	-6.51049
1866.37	-5.98716
1868.02	-5.45747
1869.66	-6.41276
1871.31	-5.44319
1872.95	-5.8263
1874.59	-5.32015
1876.23	-5.30398
1877.87	-4.63427
1879.51	-5.00133
1881.15	-6.69282
1882.79	-6.92555
1884.43	-6.28333
1886.06	-6.48469
1887.7	-7.95245
1889.34	-6.30844
1890.97	-6.59659
1892.6	-5.70611
1894.24	-4.59972
1895.87	-3.90233
1897.5	-5.63763
1899.13	-7.51135
1900.76	-5.1684
1902.39	-4.26576
1904.02	-4.11221
1905.64	-5.03675
1907.27	-5.71945
1908.9	-6.06028
1910.52	-6.54895
1912.14	-6.56004
1913.77	-5.63928
1915.39	-5.60284
1917.01	-5.20817
1918.63	-4.41841
1920.25	-4.46732
1921.87	-4.62173
1923.49	-5.13716
1925.11	-6.56144
1926.73	-6.07454
1928.34	-4.7155
1929.96	-4.56344
1931.57	-6.93056
1933.19	-7.25162
1934.8	-5.87479
1936.41	-5.2598
1938.02	-5.7682
1939.63	-6.32587
1941.24	-4.96414
1942.85	-4.87986
1944.46	-4.8909
1946.07	-6.80691
1947.67	-6.12846
1949.28	-6.16922
1950.88	-5.50505
1952.49	-5.33281
1954.09	-5.08032
1955.69	-5.0974
1957.3	-5.43481
1958.9	-5.5843
1960.5	-5.75567
1962.1	-6.25205
1963.7	-5.19738
1965.29	-5.29393
1966.89	-6.44296
1968.49	-7.05398
1970.08	-6.25995
1971.68	-5.20259
1973.27	-5.3219
1974.86	-5.5946
1976.46	-5.64659
1978.05	-5.81944
1979.64	-5.6807
1981.23	-5.65021
1982.82	-5.59186
1984.41	-4.88746
1986	-4.86793
1987.58	-4.78854
1989.17	-4.03682
1990.75	-4.35596
1992.34	-5.93433
1993.92	-6.88394
1995.51	-6.06511
1997.09	-5.673
1998.67	-6.26533
2000.25	-5.61613
2001.83	-5.18892
2003.41	-5.18802
2004.99	-4.68873
2006.56	-4.58294
2008.14	-4.93341
2009.72	-5.63605
2011.29	-6.09901
2012.87	-5.64254
2014.44	-4.70812
2016.01	-6.04358
2017.59	-4.03401
2019.16	-5.83566
2020.73	-6.63864
2022.3	-6.23423
2023.87	-4.82828
2025.43	-5.52814
2027	-6.35766
2028.57	-6.58387
2030.13	-5.92015
2031.7	-4.87157
2033.26	-4.42991
2034.83	-5.96878
2036.39	-5.11187
2037.95	-4.90415
2039.51	-4.7857
2041.07	-5.40559
2042.63	-4.88822
2044.19	-5.59417
2045.75	-6.20875
2047.31	-6.27772
2048.86	-4.78459
2050.42	-4.58023
2051.97	-4.82828
2053.53	-5.11083
2055.08	-4.86261
2056.63	-4.79105
2058.18	-5.84186
2059.74	-7.05822
2061.29	-6.42635
2062.84	-5.3538
2064.38	-4.82606
2065.93	-5.27421
2067.48	-4.90331
2069.03	-4.63141
2070.57	-6.26044
2072.12	-5.50942
2073.66	-5.14469
2075.2	-5.25156
2076.75	-5.11441
2078.29	-5.38013
2079.83	-5.76243
2081.37	-5.43541
2082.91	-5.46958
2084.45	-4.83912
2085.98	-4.50804
2087.52	-5.08383
2089.06	-6.54023
2090.59	-6.86505
2092.13	-6.92783
2093.66	-7.09552
2095.19	-6.33524
2096.73	-5.34635
2098.26	-5.08627
2099.79	-5.67017
2101.32	-5.83928
2102.85	-5.48195
2104.38	-4.86097
2105.9	-5.46085
2107.43	-5.88855
2108.96	-6.17538
2110.48	-5.13786
2112.01	-4.89727
2113.53	-5.22082
2115.05	-5.83259
2116.58	-5.86726
2118.1	-5.43866
2119.62	-5.28274
2121.14	-5.00151
2122.66	-5.59136
2124.18	-6.0938
2125.69	-6.22937
2127.21	-5.87925
2128.73	-4.82366
2130.24	-5.66731
2131.76	-6.06739
2133.27	-5.94979
2134.78	-5.61278
2136.3	-5.71816
2137.81	-5.87884
2139.32	-6.47731
2140.83	-6.38963
2142.34	-5.40028
2143.85	-5.39553
2145.35	-5.4904
2146.86	-5.55259
2148.37	-6.24766
2149.87	-6.24915
2151.38	-6.69837
2152.88	-6.06749
2154.38	-6.49362
2155.89	-5.95701
2157.39	-6.4847
2158.89	-6.26777
2160.39	-5.29723
2161.89	-5.26079
2163.39	-5.83355
2164.88	-5.65057
2166.38	-5.62656
2167.88	-6.44761
2169.37	-6.2964
2170.87	-5.71225
2172.36	-5.7148
2173.85	-6.21793
2175.35	-7.65782
2176.84	-6.92722
2178.33	-5.2644
2179.82	-5.22461
2181.31	-5.70614
2182.8	-5.70137
2184.28	-5.46943
2185.77	-6.02966
2187.26	-5.97008
2188.74	-6.31697
2190.23	-5.93804
2191.71	-6.82045
2193.19	-6.44925
2194.68	-6.54815
2196.16	-7.2052
2197.64	-6.28111
2199.12	-6.33643
2200.6	-5.9774
2202.08	-5.80048
2203.55	-5.59656
2205.03	-5.73318
2206.51	-5.90276
2207.98	-5.85712
2209.46	-5.90328
2210.93	-5.82625
2212.4	-6.25096
2213.88	-6.31205
2215.35	-5.91223
2216.82	-5.7216
2218.29	-4.89806
2219.76	-5.29097
2221.09	-6.23055
2222.61	-6.74777
2224.13	-6.52079
2225.65	-6.02722
2227.18	-5.34388
2228.7	-5.34995
2230.22	-6.39996
2231.73	-6.52079
2233.25	-6.63578
2234.77	-6.05552
2236.29	-5.75439
2237.8	-6.03819
2239.32	-6.45725
2240.83	-6.18731
2242.34	-6.07451
2243.86	-5.06984
2245.37	-5.15979
2246.88	-6.86398
2248.39	-7.12086
2249.9	-6.35314
2251.41	-6.16334
2252.92	-5.82795
2254.43	-5.28562
2255.93	-5.81756
2257.44	-5.05966
2258.95	-5.10628
2260.45	-5.17934
2261.95	-5.60635
2263.46	-6.13454
2264.96	-5.8111
2266.46	-4.70743
2267.96	-4.82022
2269.46	-4.88034
2270.96	-5.15253
2272.46	-5.99092
2273.96	-7.06866
2275.46	-5.31827
2276.95	-4.57187
2278.45	-4.39384
2279.94	-5.9504
2281.44	-7.14266
2282.93	-5.07591
2284.43	-5.76843
2285.92	-4.74932
2287.41	-3.47413
2288.9	-4.46098
2290.39	-4.64642
2291.88	-4.84924
2293.37	-4.5992
2294.86	-3.3825
2296.34	-3.38335
2297.83	-5.03976
2299.31	-4.42925
2300.8	-3.77876
2302.28	-4.06672
2303.77	-4.39294
2305.25	-4.09815
2306.73	-3.57362
2308.21	-4.12255
2309.69	-4.46768
2311.17	-5.00155
2312.65	-4.57198
2314.13	-3.15431
2315.61	-5.32464
2317.09	-4.33589
2318.56	-5.09268
2320.04	-4.60704
2321.51	-3.21498
2322.99	-3.13616
2324.46	-3.28927
2325.93	-4.14889
2327.4	-1.44157
2328.87	0.640303
2330.35	0.0308028
2331.81	-2.61739
2333.28	-4.24169
2334.75	-4.87631
2336.22	-3.83483
2337.69	-3.3115
2339.15	-3.42211
2340.62	-3.6462
2342.08	-4.53567
2343.55	-4.08469
2345.01	-3.96785
2346.47	-4.28274
2347.93	-3.82442
2349.39	-3.40767
2350.85	-2.89964
2352.31	-3.48274
2353.77	-3.60892
2355.23	-2.89686
2356.69	-2.58996
2358.14	-3.2652
2359.6	-3.42914
2361.05	-3.14232
2362.51	-3.01454
2363.96	-2.91226
2365.42	-2.25986
2366.87	-2.84738
2368.32	-3.06447
2369.77	-3.2888
2371.22	-2.94818
2372.67	-3.84375
2374.12	-4.1036
2375.56	-4.55838
2377.01	-5.03299
2378.46	-4.4029
2379.9	-3.69333
2381.35	-2.91301
2382.79	-2.63134
2384.24	-2.97717
2385.68	-2.80808
2387.12	-3.81583
2388.56	-4.05357
2390	-4.60344
2391.44	-3.44414
2392.88	-2.59734
2394.32	-2.93472
2395.76	-3.78259
2397.2	-3.89788
2398.63	-2.98465
2400.07	-2.71683
2401.5	-3.30251
2402.94	-3.63465
2404.37	-3.429
2405.8	-3.84137
2407.23	-3.90337
2408.67	-4.00065
2410.1	-4.64772
2411.53	-3.6087
2412.96	-1.73165
2414.38	-1.53986
2415.81	-2.36314
2417.24	-3.32139
2418.66	-2.44682
2420.09	-2.50203
2421.51	-2.6563
2422.94	-2.6349
2424.36	-2.55799
2425.78	-2.00592
2427.21	-1.56647
2428.63	-1.7423
2430.05	-2.09924
2431.47	-2.12717
2432.89	-2.31049
2434.3	-2.1191
2435.72	-1.56801
2437.14	-0.887855
2438.55	-0.750533
2439.97	-1.08844
2441.38	-0.628317
2442.8	0.193057
2444.21	0.415751
2445.63	-0.295379
2447.04	0.847626
2448.45	2.02311
2449.86	1.73024
2451.27	2.30489
2452.68	2.01668
2454.08	1.51892
2455.49	0.757271
2456.9	-0.0158627
2458.31	-0.112788
2459.71	-0.175647
2461.11	-0.0512233
2462.52	0.615621
2463.92	0.112356
2465.32	0.592887
2466.73	0.383693
2468.13	-0.653451
2469.53	-0.683446
2470.93	-1.36904
2472.33	-1.81696
2473.72	-2.0753
2475.12	-2.68153
2476.52	-2.94041
2477.92	-2.30121
2479.31	-1.0644
2480.7	-1.65163
2482.1	-1.48041
2483.49	-1.92717
2484.88	-1.94308
2486.28	-1.76094
2487.67	-2.09927
2489.06	-2.08167
2490.45	-1.80521
2491.84	-1.60249
2493.23	-1.50344
2494.61	-1.69951
2496	-3.49015
2497.39	-4.72444
2498.77	-4.70437
2500.16	-2.80113
2501.54	-2.45959
2502.92	-3.13961
2504.31	-3.51748
2505.69	-3.48872
2507.07	-3.19374
2508.45	-2.60167
2509.83	-2.92161
2511.21	-4.04355
2512.58	-3.27139
2513.96	-2.81156
2515.34	-3.05808
2516.72	-3.24793
2518.09	-4.3849
2519.47	-4.44291
2520.84	-3.80807
2522.21	-3.23398
2523.59	-3.14428
2524.96	-3.23571
2526.33	-3.25981
2527.7	-3.72196
2529.07	-3.58336
2530.44	-3.1787
2531.81	-2.98697
2533.17	-2.66161
2534.54	-2.887
2535.91	-2.85026
2537.27	-2.71591
2538.64	-2.98396
2540	-3.34909
2541.37	-2.68107
2542.73	-2.15722
2544.09	-1.85185
2545.45	-1.79927
2546.81	-1.88634
2548.17	-2.16081
2549.53	-2.79803
2550.89	-2.03132
2552.25	-0.726567
2553.32	-0.845438
2554.73	-0.61871
2556.14	-1.65395
2557.55	-1.45676
2558.96	-3.23164
2560.37	-2.66567
2561.77	-1.32113
2563.18	1.27222
2564.59	-0.148315
2565.99	-3.73129
2567.4	-0.246591
2568.8	1.10875
2570.2	1.94174
2571.6	2.18727
2573.01	2.81162
2574.41	2.71689
2575.81	2.34897
2577.21	2.68835
2578.6	3.86803
2580	5.07327
2581.4	5.29149
2582.8	6.53331
2584.19	7.44319
2585.59	8.95117
2586.98	9.96389
2588.38	10.3085
2589.77	11.614
2591.16	12.7383
2592.55	14.1607
2593.94	15.172
2595.33	17.5457
2596.73	22.3715
2598.11	26.4552
2599.5	29.1221
2600.89	31.7411
2602.28	36.6252
2603.66	40.737
2605.05	45.1353
2606.43	52.3067
2607.82	59.2317
2609.2	66.2371
2610.59	73.1738
2611.97	82.9116
2613.35	92.0817
2614.73	100.976
2616.11	110.221
2617.49	119.322
2618.87	123.503
2620.25	129.25
2621.63	133.785
2623	135.39
2624.38	134.654
2625.75	131.966
2627.13	127.637
2628.5	119.154
2629.88	112.077
2631.25	107.73
2632.62	104.333
2633.99	96.7791
2635.36	89.826
2636.73	79.1392
2638.1	68.122
2639.47	58.9162
2640.84	52.5782
2642.21	46.9145
2643.57	41.0856
2644.94	36.0805
2646.31	31.323
2647.67	26.7605
2649.03	22.5469
2650.4	21.0551
2651.76	19.1801
2653.12	15.7556
2654.48	13.0788
2655.84	11.2315
2657.2	10.938
2658.56	11.1074
2659.92	9.81473
2661.28	8.31871
2662.64	6.76437
2663.99	5.6248
2665.35	4.29428
2666.7	3.21949
2668.06	2.99515
2669.41	2.94165
2670.77	1.39349
2672.12	1.0979
2673.47	2.15821
2674.82	2.11921
2676.17	2.1208
2677.52	1.82121
2678.87	1.87914
2680.22	1.84057
2681.57	1.77235
2682.91	0.712474
2684.26	-0.618091
2685.61	-0.669341
2686.95	0.506229
2688.3	0.334264
2689.64	0.166007
2690.98	-0.426417
2692.32	-0.663919
2693.67	-0.685337
2695.01	-1.14204
2696.35	-2.36274
2697.69	-3.16694
2699.03	-2.50977
2700.36	-1.73525
2701.7	-1.18302
2703.04	-1.34458
2704.38	-2.06231
2705.71	-2.25576
2707.05	-2.17361
2708.38	-2.1791
2709.71	-0.987616
2711.05	-0.740823
2712.38	-1.08301
2713.71	-1.93896
2715.04	-2.49697
2716.37	-3.23889
2717.7	-3.32139
2719.03	-2.78808
2720.36	-2.29227
2721.69	-2.08082
2723.01	-2.28251
2724.34	-3.20177
2725.67	-3.56121
2726.99	-3.4145
2728.31	-3.17739
2729.64	-3.64246
2730.96	-2.67151
2732.28	-1.55827
2733.6	-2.27958
2734.93	-1.91917
2736.25	-1.39082
2737.57	-1.24438
2738.88	-1.27036
2740.2	-1.76783
2741.52	-1.09665
2742.84	-0.887413
2744.15	-1.15698
2745.47	-2.10411
2746.78	-3.35096
2748.1	-3.99814
2749.41	-3.51173
2750.72	-3.01929
2752.04	-2.11312
2753.35	-1.34202
2754.66	-3.44962
2755.97	-1.10061
2757.28	-1.7568
2758.59	-1.81703
2759.9	-3.0429
2761.2	-3.0513
2762.51	-2.8121
2763.82	-2.80721
2765.12	-3.93136
2766.43	-3.59321
2767.73	-2.92002
2769.03	-3.83431
2770.34	-2.64461
2771.64	-3.32763
2772.94	-3.09607
2774.24	-3.09713
2775.54	-2.19622
2776.84	-1.86304
2778.14	-2.5112
2779.44	-2.92958
2780.73	-3.78737
2782.03	-4.13057
2783.33	-3.30429
2784.62	-2.39491
2785.92	-2.29136
2787.21	-3.05366
2788.51	-2.80964
2789.8	-2.93366
2791.09	-2.39328
2792.38	-2.67392
2793.67	-4.19813
2794.96	-5.37097
2796.25	-5.2057
2797.54	-4.5667
2798.83	-3.36628
2800.12	-3.39196
2801.4	-4.03434
2802.69	-4.18325
2803.98	-3.39758
2805.26	-3.15674
2806.55	-3.08541
2807.83	-2.86246
2809.11	-3.27097
2810.39	-3.59651
2811.68	-3.83075
2812.96	-3.45277
2814.24	-3.49134
2815.52	-3.98756
2816.8	-3.9591
2818.07	-3.91141
2819.35	-3.84877
2820.63	-3.35371
2821.9	-3.2786
2823.18	-2.91681
2824.46	-2.53193
2825.73	-3.19477
2827	-4.11352
2828.27	-4.12748
2829.55	-4.31265
2830.82	-4.30013
2832.09	-4.20461
2833.36	-4.43374
2834.63	-4.28097
2835.9	-3.01135
2837.17	-3.00848
2838.44	-3.29319
2839.7	-3.15218
2840.97	-2.96582
2842.23	-3.20936
2843.5	-3.34658
2844.76	-3.66944
2846.03	-3.21241
2847.29	-3.71405
2848.55	-3.90733
2849.81	-4.10429
2851.08	-3.42815
2852.34	-3.36689
2853.6	-2.61046
2854.85	-2.59067
2856.11	-2.97671
2857.37	-3.70558
2858.63	-4.55828
2859.88	-4.65959
2861.11	-4.16042
2862.42	-3.3186
2863.73	-4.08472
2865.03	-2.9038
2866.34	-4.21844
2867.64	-2.12436
2868.95	-1.98843
2870.25	-1.72455
2871.56	-3.18343
2872.86	-4.59661
2874.16	-4.12086
2875.46	-3.47047
2876.76	-3.03661
2878.06	-2.99236
2879.36	-4.38611
2880.66	-4.2524
2881.96	-4.56873
2883.25	-3.1581
2884.55	-2.98007
2885.85	-3.01867
2887.14	-3.88559
2888.44	-3.54148
2889.73	-3.80344
2891.02	-3.78984
2892.32	-3.77578
2893.61	-3.05327
2894.9	-3.38786
2896.19	-4.37356
2897.48	-4.12614
2898.77	-3.98867
2900.06	-3.02356
2901.35	-2.39384
2902.64	-3.54403
2903.92	-4.28143
2905.21	-4.20856
2906.5	-4.1361
2907.78	-4.69635
2909.07	-3.89042
2910.35	-3.76378
2911.63	-4.02799
2912.92	-4.06334
2914.2	-4.55511
2915.48	-4.35048
2916.76	-4.07983
2918.04	-2.43605
2919.32	-2.62404
2920.6	-2.74766
2921.88	-2.90992
2923.16	-1.89789
2924.43	-2.11481
2925.71	-3.86904
2926.98	-4.64823
2928.26	-3.12197
2929.53	-2.1923
2930.81	-2.24389
2932.08	-3.13564
2933.35	-3.0258
2934.63	-1.56483
2935.9	-1.08476
2937.17	-2.77953
2938.44	-6.60328
2939.71	-3.5665
2940.98	-4.77222
2942.24	-4.15778
2943.51	-4.37933
2944.78	-4.44033
2946.04	-4.66487
2947.31	-3.42803
2948.57	-3.24424
2949.84	-3.84539
2951.1	-3.65388
2952.37	-3.55886
2953.63	-3.78135
2954.89	-2.80748
2956.15	-2.35915
2957.41	-2.69687
2958.67	-4.53233
2959.93	-6.72934
2961.19	-5.90127
2962.45	-4.95281
2963.71	-3.69834
2964.96	-4.73131
2966.22	-4.90795
2967.47	-3.9866
2968.73	-3.2291
2969.98	-2.83299
2971.24	-3.68733
2972.49	-4.68409
2973.74	-3.78572
2974.99	-2.80424
2976.24	-2.99279
2977.49	-3.55225
2978.74	-3.51883
2979.99	-3.53635
2981.24	-4.235
2982.49	-3.90813
2983.74	-4.39443
2984.98	-4.55272
2986.23	-4.64084
2987.47	-4.22928
2988.72	-3.61539
2989.96	-2.96292
2991.21	-3.37435
2992.45	-2.47911
2993.69	-2.36672
2994.93	-3.13594
2996.17	-3.67162
2997.42	-4.70652
2998.65	-4.05882
2999.89	-4.61349